Exception on / [GET]
Traceback (most recent call last):
  File "/home/fagan/hackedNews/hackedNews/lib/python3.8/site-packages/flask/app.py", line 2525, in wsgi_app
    response = self.full_dispatch_request()
  File "/home/fagan/hackedNews/hackedNews/lib/python3.8/site-packages/flask/app.py", line 1822, in full_dispatch_request
    rv = self.handle_user_exception(e)
  File "/home/fagan/hackedNews/hackedNews/lib/python3.8/site-packages/flask/app.py", line 1820, in full_dispatch_request
    rv = self.dispatch_request()
  File "/home/fagan/hackedNews/hackedNews/lib/python3.8/site-packages/flask/app.py", line 1796, in dispatch_request
    return self.ensure_sync(self.view_functions[rule.endpoint])(**view_args)
  File "/home/fagan/hackedNews/hackedNews.py", line 44, in home
    res = Response(render_template('index.html', data=data, session=session.get('user'), pretty=json.dumps(session.get('user'), indent=4)))
NameError: name 'data' is not defined
Exception on /account [GET]
Traceback (most recent call last):
  File "/home/fagan/hackedNews/hackedNews/lib/python3.8/site-packages/flask/app.py", line 2525, in wsgi_app
    response = self.full_dispatch_request()
  File "/home/fagan/hackedNews/hackedNews/lib/python3.8/site-packages/flask/app.py", line 1822, in full_dispatch_request
    rv = self.handle_user_exception(e)
  File "/home/fagan/hackedNews/hackedNews/lib/python3.8/site-packages/flask/app.py", line 1820, in full_dispatch_request
    rv = self.dispatch_request()
  File "/home/fagan/hackedNews/hackedNews/lib/python3.8/site-packages/flask/app.py", line 1796, in dispatch_request
    return self.ensure_sync(self.view_functions[rule.endpoint])(**view_args)
  File "/home/fagan/hackedNews/hackedNews.py", line 64, in account
    res = Response(render_template('account.html', data=data, session=session.get('user'), pretty=json.dumps(session.get('user'), indent=4)))
  File "/home/fagan/hackedNews/hackedNews/lib/python3.8/site-packages/flask/templating.py", line 147, in render_template
    return _render(app, template, context)
  File "/home/fagan/hackedNews/hackedNews/lib/python3.8/site-packages/flask/templating.py", line 130, in _render
    rv = template.render(context)
  File "/home/fagan/hackedNews/hackedNews/lib/python3.8/site-packages/jinja2/environment.py", line 1301, in render
    self.environment.handle_exception()
  File "/home/fagan/hackedNews/hackedNews/lib/python3.8/site-packages/jinja2/environment.py", line 936, in handle_exception
    raise rewrite_traceback_stack(source=source)
  File "/home/fagan/hackedNews/templates/account.html", line 32, in top-level template code
    <span id="profile_image"><img src={{ session["userinfo"]["picture"] }} /></span>
  File "/home/fagan/hackedNews/hackedNews/lib/python3.8/site-packages/jinja2/environment.py", line 466, in getitem
    return obj[argument]
jinja2.exceptions.UndefinedError: 'None' has no attribute 'userinfo'
Exception on /account [GET]
Traceback (most recent call last):
  File "/home/fagan/hackedNews/hackedNews/lib/python3.8/site-packages/flask/app.py", line 2525, in wsgi_app
    response = self.full_dispatch_request()
  File "/home/fagan/hackedNews/hackedNews/lib/python3.8/site-packages/flask/app.py", line 1822, in full_dispatch_request
    rv = self.handle_user_exception(e)
  File "/home/fagan/hackedNews/hackedNews/lib/python3.8/site-packages/flask/app.py", line 1820, in full_dispatch_request
    rv = self.dispatch_request()
  File "/home/fagan/hackedNews/hackedNews/lib/python3.8/site-packages/flask/app.py", line 1796, in dispatch_request
    return self.ensure_sync(self.view_functions[rule.endpoint])(**view_args)
  File "/home/fagan/hackedNews/hackedNews.py", line 61, in account
    res = Response(render_template('account.html', data=data, session=session.get('user'), pretty=json.dumps(session.get('user'), indent=4)))
NameError: name 'data' is not defined
Exception on /account [GET]
Traceback (most recent call last):
  File "/home/fagan/hackedNews/hackedNews/lib/python3.8/site-packages/flask/app.py", line 2525, in wsgi_app
    response = self.full_dispatch_request()
  File "/home/fagan/hackedNews/hackedNews/lib/python3.8/site-packages/flask/app.py", line 1822, in full_dispatch_request
    rv = self.handle_user_exception(e)
  File "/home/fagan/hackedNews/hackedNews/lib/python3.8/site-packages/flask/app.py", line 1820, in full_dispatch_request
    rv = self.dispatch_request()
  File "/home/fagan/hackedNews/hackedNews/lib/python3.8/site-packages/flask/app.py", line 1796, in dispatch_request
    return self.ensure_sync(self.view_functions[rule.endpoint])(**view_args)
  File "/home/fagan/hackedNews/hackedNews.py", line 61, in account
    res = Response(render_template('account.html', data=data, session=session.get('user'), pretty=json.dumps(session.get('user'), indent=4)))
NameError: name 'data' is not defined
